<?xml version="1.0"?>
<sdf version="1.4">

  <model name="pelican">
    
    <!-- Will the physics engine move this platform -->  
    <static>false</static>

    <!-- Initial pose -->
    <pose>0 0 1  0 0 0</pose>

    <!-- Frame -->
    <link name="body">
      <pose>0 0 0  0 0 0</pose>
      <inertial>
        <mass>1.680</mass>
      </inertial>
      <collision name="body_collision">
        <pose>0 0 0.035 0 0 0</pose>
        <geometry>
          <cylinder>
            <radius>.35</radius>
            <length>.08</length>
          </cylinder>
        </geometry>
      </collision>
      <visual name="body_visual">
        <pose>0 0 0 0 0 0</pose>
        <geometry>
          <mesh>
            <uri>model://pelican/meshes/pelican.dae</uri>
          </mesh>
        </geometry>
      </visual>
    </link>

    <include>
      <uri>model://blade</uri>
      <name>blade0</name>
      <pose>0.241 0.0 0.05 0 0 0</pose>
    </include>
    <joint name="motor0" type="revolute">
      <parent>body</parent>
      <child>blade0::blade_link</child>
      <axis>
        <xyz>0 0 1</xyz>
      </axis>
    </joint>

    <include>
      <uri>model://blade</uri>
      <name>blade1</name>
      <pose>-0.241 0.0 0.05 0 0 0</pose>
    </include>
    <joint name="motor1" type="revolute">
      <parent>body</parent>
      <child>blade1::blade_link</child>
      <axis>
        <xyz>0 0 1</xyz>
      </axis>
    </joint>

    <include>
      <uri>model://blade</uri>
      <name>blade2</name>
      <pose>0.0 -0.241 0.05 0 0 0</pose>
    </include>
    <joint name="motor2" type="revolute">
      <parent>body</parent>
      <child>blade2::blade_link</child>
      <axis>
        <xyz>0 0 -1</xyz>
      </axis>
    </joint>

    <include>
      <uri>model://blade</uri>
      <name>blade3</name>
      <pose>0.0 0.241 0.05 0 0 0</pose>
    </include>
    <joint name="motor3" type="revolute">
      <parent>body</parent>
      <child>blade3::blade_link</child>
      <axis>
        <xyz>0 0 -1</xyz>
      </axis>
    </joint>

    <!-- PLUGIN TO COME -->

  </model>

</sdf>